Workbook

Sheet Summary
A1: Summary
A2: All figures are formulas over the Test Cases sheet.
A4: Module | B4: Total | C4: P1 (release gate) | D4: P2 | E4: P3 | F4: Smoke | G4: Seeded-defect checks | H4: Automated | I4: Blocked | J4: Sensitive
A5: Authentication & Session | B5: =COUNTIF('Test Cases'!$C$5:$C$109,A5) -> 13 | C5: =COUNTIFS('Test Cases'!$C$5:$C$109,A5,'Test Cases'!$P$5:$P$109,"P1") -> 3 | D5: =COUNTIFS('Test Cases'!$C$5:$C$109,A5,'Test Cases'!$P$5:$P$109,"P2") -> 9 | E5: =COUNTIFS('Test Cases'!$C$5:$C$109,A5,'Test Cases'!$P$5:$P$109,"P3") -> 1 | F5: =COUNTIFS('Test Cases'!$C$5:$C$109,A5,'Test Cases'!$S$5:$S$109,"Y") -> 3 | G5: =COUNTIFS('Test Cases'!$C$5:$C$109,A5,'Test Cases'!$G$5:$G$109,"?*") -> 6 | H5: =COUNTIFS('Test Cases'!$C$5:$C$109,A5,'Test Cases'!$V$5:$V$109,"Automated") -> 13 | I5: =COUNTIFS('Test Cases'!$C$5:$C$109,A5,'Test Cases'!$V$5:$V$109,"Blocked") -> 0 | J5: =COUNTIFS('Test Cases'!$C$5:$C$109,A5,'Test Cases'!$T$5:$T$109,"Y") -> 0
A6: Agent Dashboard | B6: =COUNTIF('Test Cases'!$C$5:$C$109,A6) -> 7 | C6: =COUNTIFS('Test Cases'!$C$5:$C$109,A6,'Test Cases'!$P$5:$P$109,"P1") -> 1 | D6: =COUNTIFS('Test Cases'!$C$5:$C$109,A6,'Test Cases'!$P$5:$P$109,"P2") -> 4 | E6: =COUNTIFS('Test Cases'!$C$5:$C$109,A6,'Test Cases'!$P$5:$P$109,"P3") -> 2 | F6: =COUNTIFS('Test Cases'!$C$5:$C$109,A6,'Test Cases'!$S$5:$S$109,"Y") -> 1 | G6: =COUNTIFS('Test Cases'!$C$5:$C$109,A6,'Test Cases'!$G$5:$G$109,"?*") -> 2 | H6: =COUNTIFS('Test Cases'!$C$5:$C$109,A6,'Test Cases'!$V$5:$V$109,"Automated") -> 7 | I6: =COUNTIFS('Test Cases'!$C$5:$C$109,A6,'Test Cases'!$V$5:$V$109,"Blocked") -> 0 | J6: =COUNTIFS('Test Cases'!$C$5:$C$109,A6,'Test Cases'!$T$5:$T$109,"Y") -> 0
A7: Client / Insured Information | B7: =COUNTIF('Test Cases'!$C$5:$C$109,A7) -> 15 | C7: =COUNTIFS('Test Cases'!$C$5:$C$109,A7,'Test Cases'!$P$5:$P$109,"P1") -> 2 | D7: =COUNTIFS('Test Cases'!$C$5:$C$109,A7,'Test Cases'!$P$5:$P$109,"P2") -> 11 | E7: =COUNTIFS('Test Cases'!$C$5:$C$109,A7,'Test Cases'!$P$5:$P$109,"P3") -> 2 | F7: =COUNTIFS('Test Cases'!$C$5:$C$109,A7,'Test Cases'!$S$5:$S$109,"Y") -> 1 | G7: =COUNTIFS('Test Cases'!$C$5:$C$109,A7,'Test Cases'!$G$5:$G$109,"?*") -> 5 | H7: =COUNTIFS('Test Cases'!$C$5:$C$109,A7,'Test Cases'!$V$5:$V$109,"Automated") -> 15 | I7: =COUNTIFS('Test Cases'!$C$5:$C$109,A7,'Test Cases'!$V$5:$V$109,"Blocked") -> 0 | J7: =COUNTIFS('Test Cases'!$C$5:$C$109,A7,'Test Cases'!$T$5:$T$109,"Y") -> 4
A8: Product Selection & Policy Configuration | B8: =COUNTIF('Test Cases'!$C$5:$C$109,A8) -> 11 | C8: =COUNTIFS('Test Cases'!$C$5:$C$109,A8,'Test Cases'!$P$5:$P$109,"P1") -> 3 | D8: =COUNTIFS('Test Cases'!$C$5:$C$109,A8,'Test Cases'!$P$5:$P$109,"P2") -> 8 | E8: =COUNTIFS('Test Cases'!$C$5:$C$109,A8,'Test Cases'!$P$5:$P$109,"P3") -> 0 | F8: =COUNTIFS('Test Cases'!$C$5:$C$109,A8,'Test Cases'!$S$5:$S$109,"Y") -> 1 | G8: =COUNTIFS('Test Cases'!$C$5:$C$109,A8,'Test Cases'!$G$5:$G$109,"?*") -> 5 | H8: =COUNTIFS('Test Cases'!$C$5:$C$109,A8,'Test Cases'!$V$5:$V$109,"Automated") -> 11 | I8: =COUNTIFS('Test Cases'!$C$5:$C$109,A8,'Test Cases'!$V$5:$V$109,"Blocked") -> 0 | J8: =COUNTIFS('Test Cases'!$C$5:$C$109,A8,'Test Cases'!$T$5:$T$109,"Y") -> 0
A9: Rider Selection | B9: =COUNTIF('Test Cases'!$C$5:$C$109,A9) -> 7 | C9: =COUNTIFS('Test Cases'!$C$5:$C$109,A9,'Test Cases'!$P$5:$P$109,"P1") -> 1 | D9: =COUNTIFS('Test Cases'!$C$5:$C$109,A9,'Test Cases'!$P$5:$P$109,"P2") -> 6 | E9: =COUNTIFS('Test Cases'!$C$5:$C$109,A9,'Test Cases'!$P$5:$P$109,"P3") -> 0 | F9: =COUNTIFS('Test Cases'!$C$5:$C$109,A9,'Test Cases'!$S$5:$S$109,"Y") -> 1 | G9: =COUNTIFS('Test Cases'!$C$5:$C$109,A9,'Test Cases'!$G$5:$G$109,"?*") -> 3 | H9: =COUNTIFS('Test Cases'!$C$5:$C$109,A9,'Test Cases'!$V$5:$V$109,"Automated") -> 7 | I9: =COUNTIFS('Test Cases'!$C$5:$C$109,A9,'Test Cases'!$V$5:$V$109,"Blocked") -> 0 | J9: =COUNTIFS('Test Cases'!$C$5:$C$109,A9,'Test Cases'!$T$5:$T$109,"Y") -> 0
A10: Beneficiary Management | B10: =COUNTIF('Test Cases'!$C$5:$C$109,A10) -> 11 | C10: =COUNTIFS('Test Cases'!$C$5:$C$109,A10,'Test Cases'!$P$5:$P$109,"P1") -> 2 | D10: =COUNTIFS('Test Cases'!$C$5:$C$109,A10,'Test Cases'!$P$5:$P$109,"P2") -> 7 | E10: =COUNTIFS('Test Cases'!$C$5:$C$109,A10,'Test Cases'!$P$5:$P$109,"P3") -> 2 | F10: =COUNTIFS('Test Cases'!$C$5:$C$109,A10,'Test Cases'!$S$5:$S$109,"Y") -> 1 | G10: =COUNTIFS('Test Cases'!$C$5:$C$109,A10,'Test Cases'!$G$5:$G$109,"?*") -> 4 | H10: =COUNTIFS('Test Cases'!$C$5:$C$109,A10,'Test Cases'!$V$5:$V$109,"Automated") -> 11 | I10: =COUNTIFS('Test Cases'!$C$5:$C$109,A10,'Test Cases'!$V$5:$V$109,"Blocked") -> 0 | J10: =COUNTIFS('Test Cases'!$C$5:$C$109,A10,'Test Cases'!$T$5:$T$109,"Y") -> 0
A11: Document Upload | B11: =COUNTIF('Test Cases'!$C$5:$C$109,A11) -> 4 | C11: =COUNTIFS('Test Cases'!$C$5:$C$109,A11,'Test Cases'!$P$5:$P$109,"P1") -> 1 | D11: =COUNTIFS('Test Cases'!$C$5:$C$109,A11,'Test Cases'!$P$5:$P$109,"P2") -> 3 | E11: =COUNTIFS('Test Cases'!$C$5:$C$109,A11,'Test Cases'!$P$5:$P$109,"P3") -> 0 | F11: =COUNTIFS('Test Cases'!$C$5:$C$109,A11,'Test Cases'!$S$5:$S$109,"Y") -> 1 | G11: =COUNTIFS('Test Cases'!$C$5:$C$109,A11,'Test Cases'!$G$5:$G$109,"?*") -> 1 | H11: =COUNTIFS('Test Cases'!$C$5:$C$109,A11,'Test Cases'!$V$5:$V$109,"Automated") -> 4 | I11: =COUNTIFS('Test Cases'!$C$5:$C$109,A11,'Test Cases'!$V$5:$V$109,"Blocked") -> 0 | J11: =COUNTIFS('Test Cases'!$C$5:$C$109,A11,'Test Cases'!$T$5:$T$109,"Y") -> 0
A12: Validation Summary | B12: =COUNTIF('Test Cases'!$C$5:$C$109,A12) -> 3 | C12: =COUNTIFS('Test Cases'!$C$5:$C$109,A12,'Test Cases'!$P$5:$P$109,"P1") -> 1 | D12: =COUNTIFS('Test Cases'!$C$5:$C$109,A12,'Test Cases'!$P$5:$P$109,"P2") -> 1 | E12: =COUNTIFS('Test Cases'!$C$5:$C$109,A12,'Test Cases'!$P$5:$P$109,"P3") -> 1 | F12: =COUNTIFS('Test Cases'!$C$5:$C$109,A12,'Test Cases'!$S$5:$S$109,"Y") -> 0 | G12: =COUNTIFS('Test Cases'!$C$5:$C$109,A12,'Test Cases'!$G$5:$G$109,"?*") -> 1 | H12: =COUNTIFS('Test Cases'!$C$5:$C$109,A12,'Test Cases'!$V$5:$V$109,"Automated") -> 3 | I12: =COUNTIFS('Test Cases'!$C$5:$C$109,A12,'Test Cases'!$V$5:$V$109,"Blocked") -> 0 | J12: =COUNTIFS('Test Cases'!$C$5:$C$109,A12,'Test Cases'!$T$5:$T$109,"Y") -> 0
A13: Submission & Status Tracking | B13: =COUNTIF('Test Cases'!$C$5:$C$109,A13) -> 8 | C13: =COUNTIFS('Test Cases'!$C$5:$C$109,A13,'Test Cases'!$P$5:$P$109,"P1") -> 3 | D13: =COUNTIFS('Test Cases'!$C$5:$C$109,A13,'Test Cases'!$P$5:$P$109,"P2") -> 4 | E13: =COUNTIFS('Test Cases'!$C$5:$C$109,A13,'Test Cases'!$P$5:$P$109,"P3") -> 1 | F13: =COUNTIFS('Test Cases'!$C$5:$C$109,A13,'Test Cases'!$S$5:$S$109,"Y") -> 3 | G13: =COUNTIFS('Test Cases'!$C$5:$C$109,A13,'Test Cases'!$G$5:$G$109,"?*") -> 4 | H13: =COUNTIFS('Test Cases'!$C$5:$C$109,A13,'Test Cases'!$V$5:$V$109,"Automated") -> 8 | I13: =COUNTIFS('Test Cases'!$C$5:$C$109,A13,'Test Cases'!$V$5:$V$109,"Blocked") -> 0 | J13: =COUNTIFS('Test Cases'!$C$5:$C$109,A13,'Test Cases'!$T$5:$T$109,"Y") -> 0
A14: API Validation | B14: =COUNTIF('Test Cases'!$C$5:$C$109,A14) -> 12 | C14: =COUNTIFS('Test Cases'!$C$5:$C$109,A14,'Test Cases'!$P$5:$P$109,"P1") -> 2 | D14: =COUNTIFS('Test Cases'!$C$5:$C$109,A14,'Test Cases'!$P$5:$P$109,"P2") -> 10 | E14: =COUNTIFS('Test Cases'!$C$5:$C$109,A14,'Test Cases'!$P$5:$P$109,"P3") -> 0 | F14: =COUNTIFS('Test Cases'!$C$5:$C$109,A14,'Test Cases'!$S$5:$S$109,"Y") -> 2 | G14: =COUNTIFS('Test Cases'!$C$5:$C$109,A14,'Test Cases'!$G$5:$G$109,"?*") -> 6 | H14: =COUNTIFS('Test Cases'!$C$5:$C$109,A14,'Test Cases'!$V$5:$V$109,"Automated") -> 12 | I14: =COUNTIFS('Test Cases'!$C$5:$C$109,A14,'Test Cases'!$V$5:$V$109,"Blocked") -> 0 | J14: =COUNTIFS('Test Cases'!$C$5:$C$109,A14,'Test Cases'!$T$5:$T$109,"Y") -> 0
A15: Database Validation | B15: =COUNTIF('Test Cases'!$C$5:$C$109,A15) -> 10 | C15: =COUNTIFS('Test Cases'!$C$5:$C$109,A15,'Test Cases'!$P$5:$P$109,"P1") -> 0 | D15: =COUNTIFS('Test Cases'!$C$5:$C$109,A15,'Test Cases'!$P$5:$P$109,"P2") -> 10 | E15: =COUNTIFS('Test Cases'!$C$5:$C$109,A15,'Test Cases'!$P$5:$P$109,"P3") -> 0 | F15: =COUNTIFS('Test Cases'!$C$5:$C$109,A15,'Test Cases'!$S$5:$S$109,"Y") -> 0 | G15: =COUNTIFS('Test Cases'!$C$5:$C$109,A15,'Test Cases'!$G$5:$G$109,"?*") -> 0 | H15: =COUNTIFS('Test Cases'!$C$5:$C$109,A15,'Test Cases'!$V$5:$V$109,"Automated") -> 0 | I15: =COUNTIFS('Test Cases'!$C$5:$C$109,A15,'Test Cases'!$V$5:$V$109,"Blocked") -> 10 | J15: =COUNTIFS('Test Cases'!$C$5:$C$109,A15,'Test Cases'!$T$5:$T$109,"Y") -> 0
A16: Framework Self-Checks | B16: =COUNTIF('Test Cases'!$C$5:$C$109,A16) -> 4 | C16: =COUNTIFS('Test Cases'!$C$5:$C$109,A16,'Test Cases'!$P$5:$P$109,"P1") -> 0 | D16: =COUNTIFS('Test Cases'!$C$5:$C$109,A16,'Test Cases'!$P$5:$P$109,"P2") -> 4 | E16: =COUNTIFS('Test Cases'!$C$5:$C$109,A16,'Test Cases'!$P$5:$P$109,"P3") -> 0 | F16: =COUNTIFS('Test Cases'!$C$5:$C$109,A16,'Test Cases'!$S$5:$S$109,"Y") -> 0 | G16: =COUNTIFS('Test Cases'!$C$5:$C$109,A16,'Test Cases'!$G$5:$G$109,"?*") -> 1 | H16: =COUNTIFS('Test Cases'!$C$5:$C$109,A16,'Test Cases'!$V$5:$V$109,"Automated") -> 4 | I16: =COUNTIFS('Test Cases'!$C$5:$C$109,A16,'Test Cases'!$V$5:$V$109,"Blocked") -> 0 | J16: =COUNTIFS('Test Cases'!$C$5:$C$109,A16,'Test Cases'!$T$5:$T$109,"Y") -> 0
A17: Total | B17: =SUM(B5:B16) -> 105 | C17: =SUM(C5:C16) -> 19 | D17: =SUM(D5:D16) -> 77 | E17: =SUM(E5:E16) -> 9 | F17: =SUM(F5:F16) -> 14 | G17: =SUM(G5:G16) -> 38 | H17: =SUM(H5:H16) -> 95 | I17: =SUM(I5:I16) -> 10 | J17: =SUM(J5:J16) -> 4
A19: P1 share of all cases (Submission 1: 50%) | B19: =C17/B17 -> 0.18095238
A20: Release gate within 15-20? | B20: =IF(AND(C17>=15,C17<=20),"Yes","No - review") -> Yes
A21: Automation coverage (automated / total) | B21: =H17/B17 -> 0.9047619
A22: Risks covered | B22: =COUNTIF('Traceability - Risks'!J5:J45,">0")&" of 41" -> 41 of 41
A23: Reported issues covered | B23: =COUNTIF('Traceability - Defects'!F5:F24,">0")&" of 20" -> 20 of 20
A25: Notes
A26: Automated = a Playwright test exists for the case. Blocked = cannot be automated yet (database access, Q04).
A27: Execution against the real lab application has NOT yet been done - see the Limitations sheet.

Sheet Test Cases
A1: Test Case Design Sheet - Insurance Order Entry Platform (Submission 2)
A2: Generated from test-design/testCases.js. Edit the .js file (single source of truth) and re-run: npm run export:testdesign && python scripts/build_test_sheet.py
A4: Test Case ID | B4: Title | C4: Module | D4: Scenario ID | E4: Source | F4: Requirement / Risk Link (Submission 1 risk IDs) | G4: Seeded Defect Theme (reported issue) | H4: Seeded Defect Catalog Code (fill when received) | I4: Test Type | J4: Layer | K4: Preconditions | L4: Test Steps | M4: Test Data | N4: Expected Result | O4: Severity | P4: Priority (P1 = release gate) | Q4: Submission 1 Priority | R4: Release Gate | S4: Smoke | T4: Sensitive Data (no trace/video) | U4: Evidence Required | V4: Automation Status | W4: Automated In | X4: Run Conditions / TBC | Y4: Open Questions | Z4: Blocked Reason | AA4: Tags
A5: TC-AUTH-V01 | B5: Valid agent logs in; dashboard URL and greeting asserted | C5: Authentication & Session | D5: AUTH-V01 | E5: S1 | F5: R01 | G5: RI-01: Valid agents cannot log in after authentication changes | I5: UI Positive | J5: UI | K5: Seeded valid agent exists and is active; browser has no session | L5: 1. Open /login 2. Enter valid agent email and password 3. Click Log in | M5: AGENT_VALID_EMAIL / AGENT_VALID_PASSWORD | N5: Browser leaves /login and lands on the dashboard; the logout control is visible | O5: Critical | P5: P1 | Q5: P1 | R5: Y | S5: Y | T5: N | U5: Screenshot attached on pass AND fail; trace/video on failure; diagnostics.json (console + 5xx) | V5: Automated | W5: tests/ui/auth.spec.js | AA5: @regression @authentication @p1 @smoke @release-gate @seeded
A6: TC-AUTH-V02 | B6: Invalid password shows correct error message | C6: Authentication & Session | D6: AUTH-V02 | E6: S1 | F6: R02 | G6: RI-02: Locked or invalid agents get incorrect / misleading messages | I6: UI Negative | J6: UI | K6: Seeded valid agent exists; browser has no session | L6: 1. Open /login 2. Enter valid email with a WRONG password 3. Click Log in | M6: AGENT_VALID_EMAIL + AGENT_INVALID_PASSWORD | N6: Stays on /login; an invalid-credentials message is shown (config/messages.js invalidCredentials); dashboard is not reachable | O6: High | P6: P2 | Q6: P1 | R6: N | S6: N | T6: N | U6: Screenshot attached on pass AND fail; trace/video on failure; diagnostics.json (console + 5xx) | V6: Automated | W6: tests/ui/auth.spec.js | AA6: @regression @authentication @p2 @seeded
A7: TC-AUTH-V03 | B7: Blank username/password show mandatory field errors | C7: Authentication & Session | D7: AUTH-V03 | E7: S1 | F7: R02 | I7: UI Negative | J7: UI | K7: Browser has no session | L7: 1. Open /login 2. Leave email and password empty 3. Click Log in | M7: none | N7: Stays on /login; each empty field is flagged as required (inline message or browser validity state) | O7: Medium | P7: P2 | Q7: P2 | R7: N | S7: N | T7: N | U7: Screenshot + trace on failure | V7: Automated | W7: tests/ui/auth.spec.js | AA7: @regression @authentication @p2
A8: TC-AUTH-V04 | B8: Logout clears session; protected route redirects to login | C8: Authentication & Session | D8: AUTH-V04 | E8: S1 | F8: R05 | I8: UI Positive | J8: UI | K8: Valid agent (AGENT_VALID) signed in via saved session; environment reachable | L8: 1. Open the dashboard 2. Click Log out 3. Navigate directly to /dashboard | M8: Generated synthetic data (utils/dataBuilder.js) | N8: After logout the login page is shown; navigating to /dashboard redirects back to /login (no stale session) | O8: High | P8: P2 | Q8: P1 | R8: N | S8: Y | T8: N | U8: Screenshot + trace on failure | V8: Automated | W8: tests/ui/auth.spec.js | AA8: @regression @authentication @p2 @smoke
A9: TC-AUTH-V05 | B9: Direct /dashboard access without login is blocked | C9: Authentication & Session | D9: AUTH-V05 | E9: S1 | F9: R04 | I9: UI Security | J9: UI | K9: Fresh browser context with no cookies or storage | L9: 1. Navigate directly to /dashboard without logging in | M9: none | N9: Redirected to /login; no dashboard content is rendered | O9: Critical | P9: P1 | Q9: P1 | R9: Y | S9: Y | T9: N | U9: Screenshot + trace on failure | V9: Automated | W9: tests/ui/auth.spec.js | AA9: @regression @authentication @p1 @smoke @release-gate
A10: TC-AUTH-V06 | B10: Locked user cannot access dashboard; lock message shown | C10: Authentication & Session | D10: AUTH-V06 | E10: S1 | F10: R02 | G10: RI-02: Locked or invalid agents get incorrect / misleading messages | I10: UI Negative | J10: UI | K10: Seeded locked agent (AGENT_LOCKED) exists | L10: 1. Open /login 2. Enter locked agent credentials 3. Click Log in 4. Navigate to /dashboard | M10: AGENT_LOCKED_EMAIL / AGENT_LOCKED_PASSWORD | N10: Stays on /login with an account-locked message (not a generic "invalid password"); /dashboard redirects to login | O10: High | P10: P1 | Q10: P1 | R10: Y | S10: N | T10: N | U10: Screenshot attached on pass AND fail; trace/video on failure; diagnostics.json (console + 5xx) | V10: Automated | W10: tests/ui/auth.spec.js | AA10: @regression @authentication @p1 @release-gate @seeded
A11: TC-AUTH-V07 | B11: Account locks after five failed attempts | C11: Authentication & Session | D11: AUTH-V07 | E11: S1 | F11: R03 | G11: RI-02: Locked or invalid agents get incorrect / misleading messages | I11: UI Boundary | J11: UI + API | K11: DISPOSABLE agent (AGENT_LOCKOUT) that may be left locked; lock rule per assumption A06/Q07 | L11: 1. Attempt login with a wrong password 4 times 2. Confirm the message is still "invalid credentials" 3. Attempt a 5th wrong login (either message is acceptable - Q07) 4. Attempt login with the CORRECT password | M11: AGENT_LOCKOUT_EMAIL; LOCKOUT_ATTEMPTS (default 5) | N11: Attempts 1-4 show invalid-credentials; after the 5th failure the CORRECT password is refused with the account-locked message | O11: High | P11: P2 | Q11: P1 | R11: N | S11: N | T11: N | U11: Screenshot attached on pass AND fail; trace/video on failure; diagnostics.json (console + 5xx) | V11: Automated | W11: tests/ui/auth.spec.js | X11: Set AGENT_LOCKOUT_EMAIL (destructive: locks the account) | AA11: @regression @authentication @p2 @seeded @api
A12: TC-AUTH-V08 | B12: Password policy rejects weak password (reset/change) | C12: Authentication & Session | D12: AUTH-V08 | E12: S1 | F12: R06 | G12: RI-03: Password policy not consistently enforced | I12: UI Negative | J12: UI | K12: DISPOSABLE reset agent (AGENT_RESET); simulated OTP known (OTP_CODE) | L12: 1. Open /forgot-password and request a reset for the reset agent 2. Enter the OTP 3. For each weak password (short, no digit, no uppercase, common word) set it as the new password | M12: AGENT_RESET_EMAIL; OTP_CODE; weak password list in tests/ui/auth.spec.js | N12: Every weak password is rejected with a password-policy message; the password is not changed | O12: Medium | P12: P2 | Q12: P2 | R12: N | S12: N | T12: N | U12: Screenshot attached on pass AND fail; trace/video on failure; diagnostics.json (console + 5xx) | V12: Automated | W12: tests/ui/auth.spec.js | X12: Set AGENT_RESET_EMAIL and OTP_CODE (Q08, Q09) | Y12: Q08, Q09 | AA12: @regression @authentication @p2 @seeded
A13: TC-AUTH-V09 | B13: MFA/OTP simulation login | C13: Authentication & Session | D13: AUTH-V09 | E13: S1+ | F13: R01 | I13: UI Positive | J13: UI | K13: Seeded MFA agent (AGENT_MFA); simulated OTP known (OTP_CODE) | L13: 1. Log in with MFA agent credentials 2. Confirm OTP prompt 3. Enter a WRONG OTP 4. Enter the correct OTP | M13: AGENT_MFA_EMAIL; OTP_CODE | N13: OTP prompt appears; wrong OTP is rejected; correct OTP completes login to the dashboard | O13: High | P13: P2 | Q13: P2 | R13: N | S13: N | T13: N | U13: Screenshot + trace on failure | V13: Automated | W13: tests/ui/auth.spec.js | X13: Set AGENT_MFA_EMAIL and OTP_CODE (Q06, Q08) | Y13: Q06, Q08 | AA13: @regression @authentication @p2
A14: TC-AUTH-V10 | B14: Session timeout redirects to login | C14: Authentication & Session | D14: AUTH-V10 | E14: S1+ | F14: R05 | I14: UI Boundary | J14: UI | K14: Valid agent (AGENT_VALID) signed in via saved session; environment reachable | L14: 1. Log in 2. Stay idle for SESSION_TIMEOUT_SECONDS + 2 seconds 3. Navigate to a protected page | M14: SESSION_TIMEOUT_SECONDS (short value on a test environment) | N14: The expired session is redirected to /login | O14: High | P14: P2 | Q14: P2 | R14: N | S14: N | T14: N | U14: Screenshot + trace on failure | V14: Automated | W14: tests/ui/auth.spec.js | X14: Set SESSION_TIMEOUT_SECONDS (Q07); keep it small | Y14: Q07 | AA14: @regression @authentication @p2
A15: TC-AUTH-V11 | B15: Forgot-password flow (/forgot-password) | C15: Authentication & Session | D15: AUTH-V11 | E15: S1+ | F15: R06 | I15: UI Positive | J15: UI | K15: Browser has no session | L15: 1. Open /login 2. Click the forgot-password link 3. Enter the agent email 4. Submit | M15: AGENT_VALID_EMAIL / AGENT_VALID_PASSWORD | N15: The forgot-password page opens and submitting a known email shows a confirmation or the OTP step (no error) | O15: Low | P15: P3 | Q15: P3 | R15: N | S15: N | T15: N | U15: Screenshot + trace on failure | V15: Automated | W15: tests/ui/auth.spec.js | AA15: @regression @authentication @p3
A16: TC-AUTH-V12 | B16: Reset OTP: wrong OTP rejected; correct OTP reaches new-password step | C16: Authentication & Session | D16: AUTH-V12 | E16: S2+ | F16: R06 | I16: UI Negative | J16: UI | K16: DISPOSABLE reset agent (AGENT_RESET); simulated OTP known (OTP_CODE) | L16: 1. Open /forgot-password and request a reset 2. Enter a WRONG OTP 3. Enter the correct OTP | M16: AGENT_RESET_EMAIL; OTP_CODE | N16: Wrong OTP shows an OTP error and does not advance; correct OTP shows the new-password fields (password is NOT changed by this test) | O16: High | P16: P2 | Q16: P2 | R16: N | S16: N | T16: N | U16: Screenshot + trace on failure | V16: Automated | W16: tests/ui/auth.spec.js | X16: Set AGENT_RESET_EMAIL and OTP_CODE (Q08) | Y16: Q08 | AA16: @regression @authentication @p2
A17: TC-AUTH-V13 | B17: New password identical to the current password is rejected | C17: Authentication & Session | D17: AUTH-V13 | E17: S2+ | F17: R06 | G17: RI-03: Password policy not consistently enforced | I17: UI Negative | J17: UI | K17: DISPOSABLE reset agent (AGENT_RESET); OTP_CODE known | L17: 1. Request reset and pass the OTP step 2. Enter the CURRENT password as the new password and confirm 3. Submit | M17: AGENT_RESET_EMAIL / AGENT_RESET_PASSWORD; OTP_CODE | N17: Rejected with a "must differ from current password" style message | O17: Medium | P17: P2 | Q17: P2 | R17: N | S17: N | T17: N | U17: Screenshot attached on pass AND fail; trace/video on failure; diagnostics.json (console + 5xx) | V17: Automated | W17: tests/ui/auth.spec.js | X17: Set AGENT_RESET_EMAIL and OTP_CODE | AA17: @regression @authentication @p2 @seeded
A18: TC-DASH-V01 | B18: Dashboard loads: draft/submitted summary and New Application CTA | C18: Agent Dashboard | D18: DASH-V01 | E18: S1 | F18: R07 | I18: UI Positive | J18: UI | K18: Valid agent (AGENT_VALID) signed in via saved session; environment reachable | L18: 1. Open the dashboard | M18: Generated synthetic data (utils/dataBuilder.js) | N18: New Application control is visible; draft and submitted summary figures are displayed as numbers | O18: High | P18: P2 | Q18: P1 | R18: N | S18: Y | T18: N | U18: Screenshot + trace on failure | V18: Automated | W18: tests/ui/dashboard.spec.js | AA18: @regression @dashboard @p2 @smoke
A19: TC-DASH-V02 | B19: Agent sees only own applications (multi-agent isolation) | C19: Agent Dashboard | D19: DASH-V02 | E19: S1 | F19: R08 | I19: UI Security | J19: UI + API | K19: Two seeded agents (AGENT_VALID, AGENT_SECOND), each with applications | L19: 1. Open dashboard as agent A and collect row identifiers 2. Open dashboard as agent B and collect row identifiers 3. Compare the two sets | M19: AGENT_VALID_*, AGENT_SECOND_* | N19: The two sets of application rows do not overlap | O19: Critical | P19: P1 | Q19: P1 | R19: Y | S19: N | T19: N | U19: Screenshot + trace on failure | V19: Automated | W19: tests/ui/dashboard.spec.js | X19: Set AGENT_SECOND_EMAIL (Q06) | Y19: Q06 | AA19: @regression @dashboard @p1 @release-gate @api
A20: TC-DASH-V03 | B20: New agent sees empty-state copy and CTA | C20: Agent Dashboard | D20: DASH-V03 | E20: S1 | F20: R07 | I20: UI Positive | J20: UI | K20: Seeded NEW agent (AGENT_NEW) with zero applications | L20: 1. Sign in as the new agent 2. Open the dashboard | M20: AGENT_NEW_* | N20: Empty-state text and the New Application control are visible; no application rows | O20: Low | P20: P3 | Q20: P3 | R20: N | S20: N | T20: N | U20: Screenshot + trace on failure | V20: Automated | W20: tests/ui/dashboard.spec.js | X20: Set AGENT_NEW_EMAIL (Q06) | Y20: Q06 | AA20: @regression @dashboard @p3
A21: TC-DASH-V04 | B21: Draft can be resumed from dashboard with saved data | C21: Agent Dashboard | D21: DASH-V04 | E21: S1 | F21: R09 | G21: RI-16: Draft data not persisted | I21: UI Positive | J21: UI | K21: Valid agent (AGENT_VALID) signed in via saved session; environment reachable; client step reachable | L21: 1. Start a new application 2. Fill the client step and Save draft 3. Go to the dashboard 4. Resume the draft row 5. Read the client first name | M21: Generated synthetic data (utils/dataBuilder.js) | N21: The resumed draft shows the client first name that was saved | O21: High | P21: P2 | Q21: P2 | R21: N | S21: N | T21: N | U21: Screenshot attached on pass AND fail; trace/video on failure; diagnostics.json (console + 5xx) | V21: Automated | W21: tests/ui/dashboard.spec.js | AA21: @regression @dashboard @p2 @seeded
A22: TC-DASH-V05 | B22: Status filters (Draft/Submitted/Approved) return correct rows | C22: Agent Dashboard | D22: DASH-V05 | E22: S1 | F22: R07 | I22: UI Positive | J22: UI | K22: Valid agent (AGENT_VALID) signed in via saved session; environment reachable | L22: 1. Open the dashboard 2. For each status filter value (Draft, Submitted, Approved) apply the filter 3. Read the status of every visible row | M22: Generated synthetic data (utils/dataBuilder.js) | N22: Every visible row has the selected status (an empty result is acceptable only if no such applications exist) | O22: Medium | P22: P2 | Q22: P2 | R22: N | S22: N | T22: N | U22: Screenshot + trace on failure | V22: Automated | W22: tests/ui/dashboard.spec.js | AA22: @regression @dashboard @p2
A23: TC-DASH-V06 | B23: Dashboard status matches Application Status API | C23: Agent Dashboard | D23: DASH-V06 | E23: S1 | F23: R07 | G23: RI-18: Dashboard status differs from backend status | I23: UI-API Integration | J23: UI + API | K23: Valid agent (AGENT_VALID) signed in via saved session; environment reachable | L23: 1. Open the dashboard and read id and status of up to 5 rows 2. Call GET /applications/{id}/status for each 3. Compare | M23: Generated synthetic data (utils/dataBuilder.js) | N23: UI status equals API status for every compared application | O23: High | P23: P2 | Q23: P1 | R23: N | S23: N | T23: N | U23: Screenshot + API response attached | V23: Automated | W23: tests/integration/ui-api.spec.js | AA23: @regression @dashboard @p2 @seeded @api
A24: TC-DASH-V07 | B24: Dashboard search returns matching applications | C24: Agent Dashboard | D24: DASH-V07 | E24: S1+ | F24: R07 | I24: UI Positive | J24: UI | K24: Valid agent (AGENT_VALID) signed in via saved session; environment reachable; at least one application exists | L24: 1. Open the dashboard 2. Take a search term from the first row 3. Search for it | M24: Generated synthetic data (utils/dataBuilder.js) | N24: At least one row is shown and every shown row contains the term | O24: Low | P24: P3 | Q24: P3 | R24: N | S24: N | T24: N | U24: Screenshot + trace on failure | V24: Automated | W24: tests/ui/dashboard.spec.js | AA24: @regression @dashboard @p3
A25: TC-CLI-V01 | B25: Valid insured personal information enables next step | C25: Client / Insured Information | D25: CLI-V01 | E25: S1 | F25: R10 | I25: UI Positive | J25: UI | K25: Valid agent (AGENT_VALID) signed in via saved session; environment reachable; NEW application open at the client step (first step) | L25: 1. Fill every client field with valid data 2. Click Next | M25: Generated synthetic data (utils/dataBuilder.js) | N25: Navigation moves to the next step (step title changes) with no validation errors | O25: Critical | P25: P2 | Q25: P1 | R25: N | S25: Y | T25: N | U25: Screenshot + trace on failure | V25: Automated | W25: tests/ui/client.spec.js | AA25: @regression @client @p2 @smoke
A26: TC-CLI-V02 | B26: Mandatory personal fields validated inline | C26: Client / Insured Information | D26: CLI-V02 | E26: S1 | F26: R10 | I26: UI Negative | J26: UI | K26: Valid agent (AGENT_VALID) signed in via saved session; environment reachable; NEW application open at the client step (first step) | L26: 1. Leave all client fields empty 2. Click Next | M26: none | N26: User stays on the step; first name, last name and date of birth each show a required message | O26: Medium | P26: P2 | Q26: P2 | R26: N | S26: N | T26: N | U26: Screenshot + trace on failure | V26: Automated | W26: tests/ui/client.spec.js | AA26: @regression @client @p2
A27: TC-CLI-V03 | B27: DOB under 18 rejected (age boundary) | C27: Client / Insured Information | D27: CLI-V03 | E27: S1 | F27: R10 | G27: RI-04: Client age eligibility rules (18-65) missed | I27: UI Boundary | J27: UI + API | K27: Valid agent (AGENT_VALID) signed in via saved session; environment reachable; NEW application open at the client step (first step) | L27: 1. Enter DOB for a person who turns 18 TOMORROW (age 17) and click Next 2. Enter DOB for a person exactly 18 today and click Next | M27: dobForAge(18,{dayOffset:1}) and dobForAge(18) | N27: Age 17 is rejected with an eligibility message and the step does not advance; age 18 is accepted (inclusive rule - assumption A06 / Q10) | O27: High | P27: P2 | Q27: P1 | R27: N | S27: N | T27: N | U27: Screenshot attached on pass AND fail; trace/video on failure; diagnostics.json (console + 5xx) | V27: Automated | W27: tests/ui/client.spec.js | AA27: @regression @client @p2 @seeded @api
A28: TC-CLI-V04 | B28: DOB over 65 rejected (age boundary) | C28: Client / Insured Information | D28: CLI-V04 | E28: S1 | F28: R10 | G28: RI-04: Client age eligibility rules (18-65) missed | I28: UI Boundary | J28: UI + API | K28: Valid agent (AGENT_VALID) signed in via saved session; environment reachable; NEW application open at the client step (first step) | L28: 1. Enter DOB for a person exactly 66 years old and click Next 2. Enter DOB for a person exactly 65 today and click Next | M28: dobForAge(66) and dobForAge(65) | N28: Age 66 is rejected with an eligibility message; age 65 is accepted (inclusive rule - A06 / Q10) | O28: High | P28: P2 | Q28: P1 | R28: N | S28: N | T28: N | U28: Screenshot attached on pass AND fail; trace/video on failure; diagnostics.json (console + 5xx) | V28: Automated | W28: tests/ui/client.spec.js | AA28: @regression @client @p2 @seeded @api
A29: TC-CLI-V05 | B29: Future DOB rejected | C29: Client / Insured Information | D29: CLI-V05 | E29: S1 | F29: R11 | G29: RI-05: Future date of birth accepted | I29: UI Negative | J29: UI + API | K29: Valid agent (AGENT_VALID) signed in via saved session; environment reachable; NEW application open at the client step (first step) | L29: 1. Enter a DOB of tomorrow and click Next 2. Enter a DOB 5 years in the future and click Next | M29: futureDate(1), futureDate(1825) | N29: Both dates are rejected with an invalid-date message and the step does not advance | O29: High | P29: P1 | Q29: P1 | R29: Y | S29: N | T29: N | U29: Screenshot attached on pass AND fail; trace/video on failure; diagnostics.json (console + 5xx) | V29: Automated | W29: tests/ui/client.spec.js | AA29: @regression @client @p1 @release-gate @seeded @api
A30: TC-CLI-V06 | B30: Same-as-residential copies address to mailing address | C30: Client / Insured Information | D30: CLI-V06 | E30: S1 | F30: R15 | I30: UI Positive | J30: UI | K30: Valid agent (AGENT_VALID) signed in via saved session; environment reachable; NEW application open at the address step with every earlier step completed using valid data | L30: 1. Fill the residential address 2. Tick "same as residential" 3. Read the mailing address fields | M30: Generated synthetic data (utils/dataBuilder.js) | N30: Mailing line 1, city and ZIP equal the residential values | O30: Low | P30: P3 | Q30: P3 | R30: N | S30: N | T30: N | U30: Screenshot + trace on failure | V30: Automated | W30: tests/ui/client.spec.js | AA30: @regression @client @p3
A31: TC-CLI-V07 | B31: Invalid email and phone formats rejected | C31: Client / Insured Information | D31: CLI-V07 | E31: S1 | F31: R15 | I31: UI Negative | J31: UI | K31: Valid agent (AGENT_VALID) signed in via saved session; environment reachable; NEW application open at the address step with every earlier step completed using valid data | L31: 1. Fill a valid address 2. For each invalid email (no @, no domain, spaces) enter it and click Next 3. For each invalid phone (letters, too short) enter it and click Next | M31: Invalid email / phone lists in tests/ui/client.spec.js | N31: Each invalid value shows a format error next to the field and the step does not advance | O31: Medium | P31: P2 | Q31: P2 | R31: N | S31: N | T31: N | U31: Screenshot + trace on failure | V31: Automated | W31: tests/ui/client.spec.js | AA31: @regression @client @p2
A32: TC-CLI-V08 | B32: SSN masked after entry (only last four digits visible) | C32: Client / Insured Information | D32: CLI-V08 | E32: S1 | F32: R12 | G32: RI-07: SSN not masked properly | I32: UI Security | J32: UI | K32: Valid agent (AGENT_VALID) signed in via saved session; environment reachable; NEW application open at the kyc step with every earlier step completed using valid data | L32: 1. Enter the synthetic SSN 900-12-3456 2. Leave the field (blur) 3. Read what is visible for the SSN | M32: Synthetic SSN 900-12-3456 (900-series is never issued) | N32: Only the last four digits (3456) are visible; the first five digits are masked | O32: Critical | P32: P1 | Q32: P1 | R32: Y | S32: N | T32: Y | U32: Screenshot attached on pass AND fail; trace/video on failure; diagnostics.json (console + 5xx) | V32: Automated | W32: tests/ui/client-kyc-sensitive.spec.js | AA32: @regression @client @p1 @release-gate @sensitive @seeded
A33: TC-CLI-V09 | B33: KYC upload rejects unsupported file type | C33: Client / Insured Information | D33: CLI-V09 | E33: S1 | F33: R30 | I33: UI Negative | J33: UI | K33: Valid agent (AGENT_VALID) signed in via saved session; environment reachable; NEW application open at the kyc step with every earlier step completed using valid data | L33: 1. Upload an .exe file in the KYC document control | M33: In-memory malware-test.exe | N33: An unsupported-type message is shown and the file is not accepted | O33: Medium | P33: P2 | Q33: P2 | R33: N | S33: N | T33: Y | U33: Screenshot + trace on failure | V33: Automated | W33: tests/ui/client-kyc-sensitive.spec.js | X33: Skips if the KYC step has no upload control | AA33: @regression @client @p2 @sensitive
A34: TC-CLI-V10 | B34: PEP = Yes makes additional details mandatory | C34: Client / Insured Information | D34: CLI-V10 | E34: S1 | F34: R14 | I34: UI Negative | J34: UI | K34: Valid agent (AGENT_VALID) signed in via saved session; environment reachable; NEW application open at the kyc step with every earlier step completed using valid data | L34: 1. Select PEP = Yes 2. Confirm the PEP details field appears 3. Click Next without details | M34: Generated synthetic data (utils/dataBuilder.js) | N34: PEP details field becomes visible and Next is blocked with a required message until it is filled | O34: Medium | P34: P2 | Q34: P2 | R34: N | S34: N | T34: Y | U34: Screenshot + trace on failure | V34: Automated | W34: tests/ui/client-kyc-sensitive.spec.js | AA34: @regression @client @p2 @sensitive
A35: TC-CLI-V11 | B35: Postal code format validated | C35: Client / Insured Information | D35: CLI-V11 | E35: S1+ | F35: R15 | I35: UI Negative | J35: UI | K35: Valid agent (AGENT_VALID) signed in via saved session; environment reachable; NEW application open at the address step with every earlier step completed using valid data | L35: 1. Fill a valid address with an invalid ZIP (letters, too short, too long) 2. Click Next | M35: ZIPs: ABCDE, 123, 0211000000 | N35: Each invalid ZIP is rejected with a postal-code message | O35: Low | P35: P3 | Q35: P3 | R35: N | S35: N | T35: N | U35: Screenshot + trace on failure | V35: Automated | W35: tests/ui/client.spec.js | AA35: @regression @client @p3
A36: TC-CLI-V12 | B36: Income vs premium affordability validation | C36: Client / Insured Information | D36: CLI-V12 | E36: S1+ | F36: R13 | G36: RI-08: Income vs premium affordability not applied | I36: UI Negative | J36: UI + API | K36: Valid agent (AGENT_VALID) signed in via saved session; environment reachable; NEW application open at the kyc step with every earlier step completed using valid data | L36: 1. Enter a very LOW annual income 2. Continue to Product and select a product with a very HIGH face value 3. Click Next | M36: income 12000; face value 5,000,000 (rule undefined - Q11) | N36: An affordability warning or block referring to income/premium is shown (formula TBC with the product owner) | O36: High | P36: P2 | Q36: P1 | R36: N | S36: N | T36: Y | U36: Screenshot attached on pass AND fail; trace/video on failure; diagnostics.json (console + 5xx) | V36: Automated | W36: tests/ui/client-kyc-sensitive.spec.js | AA36: @regression @client @p2 @sensitive @seeded @api
A37: TC-CLI-V13 | B37: Calculated age is displayed after DOB entry | C37: Client / Insured Information | D37: CLI-V13 | E37: S2+ | F37: R10 | I37: UI Positive | J37: UI | K37: Valid agent (AGENT_VALID) signed in via saved session; environment reachable; NEW application open at the client step (first step) | L37: 1. Enter a DOB for each of ages 18, 35 and 65 2. Read the displayed age | M37: dobForAge(18|35|65) | N37: The age shown equals the age calculated from the DOB (calcAge in utils/dates.js) | O37: Medium | P37: P2 | Q37: P2 | R37: N | S37: N | T37: N | U37: Screenshot + trace on failure | V37: Automated | W37: tests/ui/client.spec.js | AA37: @regression @client @p2
A38: TC-CLI-V14 | B38: Name validation rejects digits and special characters | C38: Client / Insured Information | D38: CLI-V14 | E38: S2+ | F38: R15 | I38: UI Negative | J38: UI | K38: Valid agent (AGENT_VALID) signed in via saved session; environment reachable; NEW application open at the client step (first step) | L38: 1. Enter a first name containing digits, click Next 2. Enter a last name containing special characters, click Next | M38: First name "J0hn123"; last name "O@#$%" | N38: Each invalid name is rejected with a name-format message and the step does not advance | O38: Medium | P38: P2 | Q38: P2 | R38: N | S38: N | T38: N | U38: Screenshot + trace on failure | V38: Automated | W38: tests/ui/client.spec.js | AA38: @regression @client @p2
A39: TC-CLI-V15 | B39: State is required and validated | C39: Client / Insured Information | D39: CLI-V15 | E39: S2+ | F39: R15 | I39: UI Negative | J39: UI | K39: Valid agent (AGENT_VALID) signed in via saved session; environment reachable; NEW application open at the address step with every earlier step completed using valid data | L39: 1. Fill a valid address but clear the state selection 2. Click Next | M39: Generated synthetic data (utils/dataBuilder.js) | N39: A state-required message is shown and the step does not advance | O39: Medium | P39: P2 | Q39: P2 | R39: N | S39: N | T39: N | U39: Screenshot + trace on failure | V39: Automated | W39: tests/ui/client.spec.js | X39: Skips if the state control has no empty option | AA39: @regression @client @p2
A40: TC-PROD-V01 | B40: Catalog displays expected Whole Life products | C40: Product Selection & Policy Configuration | D40: PROD-V01 | E40: S1 | F40: R16 | I40: UI Positive | J40: UI | K40: Valid agent (AGENT_VALID) signed in via saved session; environment reachable; NEW application open at the product step with every earlier step completed using valid data | L40: 1. Open the product step 2. Read the product cards | M40: PRODUCT_NAME_PATTERN (default "whole life") | N40: At least one product card is shown and at least one matches the Whole Life pattern | O40: High | P40: P1 | Q40: P1 | R40: Y | S40: Y | T40: N | U40: Screenshot + trace on failure | V40: Automated | W40: tests/ui/product.spec.js | AA40: @regression @product @p1 @smoke @release-gate
A41: TC-PROD-V02 | B41: Product details page shows features, eligibility, limits | C41: Product Selection & Policy Configuration | D41: PROD-V02 | E41: S1 | F41: R16 | I41: UI Positive | J41: UI | K41: Valid agent (AGENT_VALID) signed in via saved session; environment reachable; NEW application open at the product step with every earlier step completed using valid data | L41: 1. Open the details of the first product | M41: Generated synthetic data (utils/dataBuilder.js) | N41: Details mention features/benefits and eligibility or limits | O41: Medium | P41: P2 | Q41: P2 | R41: N | S41: N | T41: N | U41: Screenshot + trace on failure | V41: Automated | W41: tests/ui/product.spec.js | X41: Skips if no details link exists | AA41: @regression @product @p2
...

Sheet Release Gate
A1: Release Gate (P1) - the scenarios that MUST pass for a release
A2: Submission 1 rated 52 of 105 scenarios P1. P1 is now limited to these. Everything else is regression (P2) or P3. Run: npm run test:gate
A4: Test Case ID | B4: Title | C4: Why a failure blocks the release | D4: Layer | E4: Automation Status | F4: Linked Risks
A5: TC-AUTH-V01 | B5: Valid agent logs in; dashboard URL and greeting asserted | C5: If valid agents cannot sign in, nothing else is usable. | D5: UI | E5: Automated | F5: R01
A6: TC-AUTH-V05 | B6: Direct /dashboard access without login is blocked | C6: Protected pages must not be reachable without a session. | D6: UI | E6: Automated | F6: R04
A7: TC-AUTH-V06 | B7: Locked user cannot access dashboard; lock message shown | C7: Locked agents must stay locked out, with the correct message. | D7: UI | E7: Automated | F7: R02
A8: TC-DASH-V02 | B8: Agent sees only own applications (multi-agent isolation) | C8: An agent must never see another agent's applications (confidentiality). | D8: UI + API | E8: Automated | F8: R08
A9: TC-CLI-V05 | B9: Future DOB rejected | C9: A future date of birth would create an invalid policy. | D9: UI + API | E9: Automated | F9: R11
A10: TC-CLI-V08 | B10: SSN masked after entry (only last four digits visible) | C10: Unmasked SSN is a compliance / privacy breach. | D10: UI | E10: Automated | F10: R12
A11: TC-PROD-V01 | B11: Catalog displays expected Whole Life products | C11: Agents cannot sell if the product catalogue does not load. | D11: UI | E11: Automated | F11: R16
A12: TC-PROD-V05 | B12: Premium recalculates when frequency changes | C12: Wrong premium after a configuration change misprices the policy. | D12: UI + API | E12: Automated | F12: R18
A13: TC-PROD-V06 | B13: Review-page premium matches configuration page | C13: Premium on review must equal what the agent configured. | D13: UI + DB | E13: Automated | F13: R18, R19
A14: TC-RIDER-V02 | B14: Rider coverage cannot exceed base face value | C14: Rider cover above the base face value is an invalid coverage. | D14: UI + API | E14: Automated | F14: R20
A15: TC-BEN-V02 | B15: Primary allocation below 100% blocks progression | C15: Allocations must total 100% or payouts are disputed. | D15: UI + API + DB | E15: Automated | F15: R24
... A23: TC-API-V05 | B23: Submit API rejects incomplete application | C23: The submit API must refuse incomplete applications. | D23: API + DB | E23: Automated | F23: R29, R35
A25: Gate size | B25: =COUNTIF('Test Cases'!$P$5:$P$109,"P1") -> 19
A26: Target | B26: 15 to 20 scenarios
A27: Within target? | B27: =IF(AND(B25>=15,B25<=20),"Yes","No - review") -> Yes

Sheet Traceability - Risks
A1: Traceability: Submission 1 risk register (R01-R41) to test cases
A2: Linked test cases are counted by formula from the Test Cases sheet.
A4: Risk ID | B4: Module | C4: Layer | D4: Risk | E4: Likelihood | F4: Impact | G4: Rating | H4: Covered by (Submission 1) | I4: Linked Test Cases | J4: # Test Cases
A5: R01 | B5: Authentication | C5: UI | D5: Valid agents cannot log in after authentication changes | E5: Medium | F5: High | G5: High | H5: AUTH-V01 | I5: TC-AUTH-V01, TC-AUTH-V09 | J5: =COUNTIF('Test Cases'!$F$5:$F$109,"*"&A5&"*") -> 2
A6: R02 | B6: Authentication | C6: UI | D6: Locked or invalid users see incorrect or misleading messages | E6: Medium | F6: Medium | G6: Medium | H6: AUTH-V02, V06 | I6: TC-AUTH-V02, TC-AUTH-V03, TC-AUTH-V06 | J6: =COUNTIF('Test Cases'!$F$5:$F$109,"*"&A6&"*") -> 3
A7: R03 | B7: Authentication | C7: API/DB | D7: Lockout after five failures not enforced server-side or counter not stored | E7: Medium | F7: High | G7: High | H7: AUTH-V07, DB-10 | I7: TC-AUTH-V07, TC-DB-10 | J7: =COUNTIF('Test Cases'!$F$5:$F$109,"*"&A7&"*") -> 2
A8: R04 | B8: Authentication | C8: API | D8: Protected pages or endpoints reachable without authentication | E8: Low | F8: High | G8: Medium | H8: AUTH-V05, API-V02 | I8: TC-AUTH-V05, TC-API-V02 | J8: =COUNTIF('Test Cases'!$F$5:$F$109,"*"&A8&"*") -> 2
A9: R05 | B9: Authentication | C9: UI/API | D9: Session not cleared on logout; no session timeout | E9: Medium | F9: High | G9: High | H9: AUTH-V04, AUTH-V10 | I9: TC-AUTH-V04, TC-AUTH-V10 | J9: =COUNTIF('Test Cases'!$F$5:$F$109,"*"&A9&"*") -> 2
A10: R06 | B10: Authentication | C10: UI | D10: Password policy inconsistently enforced | E10: Medium | F10: Medium | G10: Medium | H10: AUTH-V08 | I10: TC-AUTH-V08, TC-AUTH-V11, TC-AUTH-V12, TC-AUTH-V13 | J10: =COUNTIF('Test Cases'!$F$5:$F$109,"*"&A10&"*") -> 4
A11: R07 | B11: Dashboard | C11: UI/API/DB | D11: Dashboard status differs from backend status | E11: Medium | F11: High | G11: High | H11: DASH-V06, API-V06, DB-03 | I11: TC-DASH-V01, TC-DASH-V03, TC-DASH-V05, TC-DASH-V06, TC-DASH-V07, TC-WF-V06, TC-WF-V07, TC-API-V06, TC-DB-03 | J11: =COUNTIF('Test Cases'!$F$5:$F$109,"*"&A11&"*") -> 9
A12: R08 | B12: Dashboard | C12: API/DB | D12: Agent sees another agent's applications | E12: Low | F12: High | G12: Medium | H12: DASH-V02, API-V08, DB-09 | I12: TC-DASH-V02, TC-API-V08, TC-DB-09 | J12: =COUNTIF('Test Cases'!$F$5:$F$109,"*"&A12&"*") -> 3
A13: R09 | B13: Dashboard | C13: UI | D13: Resumed draft shows missing or stale data | E13: Medium | F13: Medium | G13: Medium | H13: DASH-V04, WF-V02 | I13: TC-DASH-V04, TC-WF-V02 | J13: =COUNTIF('Test Cases'!$F$5:$F$109,"*"&A13&"*") -> 2
A14: R10 | B14: Client / KYC | C14: UI/API | D14: Age eligibility (18-65) rules missed | E14: Medium | F14: High | G14: High | H14: CLI-V03, V04 | I14: TC-CLI-V01, TC-CLI-V02, TC-CLI-V03, TC-CLI-V04, TC-CLI-V13 | J14: =COUNTIF('Test Cases'!$F$5:$F$109,"*"&A14&"*") -> 5
A15: R11 | B15: Client / KYC | C15: UI/API | D15: Future date of birth accepted | E15: Medium | F15: High | G15: High | H15: CLI-V05, API-V03 | I15: TC-CLI-V05, TC-API-V03 | J15: =COUNTIF('Test Cases'!$F$5:$F$109,"*"&A15&"*") -> 2
A16: R12 | B16: Client / KYC | C16: UI/DB | D16: SSN displayed unmasked, or stored/logged in clear text | E16: Medium | F16: High | G16: High | H16: CLI-V08, DB-07 | I16: TC-CLI-V08, TC-DB-07 | J16: =COUNTIF('Test Cases'!$F$5:$F$109,"*"&A16&"*") -> 2
... A45: R41 | B45: Cross-cutting | C45: DB | D45: Database access or schema not available for backend validation | E45: Medium | F45: Medium | G45: Medium | H45: DB-01..DB-10 | I45: TC-DB-01, TC-DB-02, TC-DB-03, TC-DB-04, TC-DB-05, TC-DB-06, TC-DB-07, TC-DB-08, TC-DB-09, TC-DB-10 | J45: =COUNTIF('Test Cases'!$F$5:$F$109,"*"&A45&"*") -> 10
A47: Risks with no test case | D47: =COUNTIF(J5:J45,0) -> 0

Sheet Traceability - Defects
A1: Traceability: seeded-defect themes (20 reported issues) to test cases
A2: No official seeded-defect catalog was available (Submission 1 question Q05). Fill column D when it is received.
A4: Reported Issue ID | B4: Module | C4: Description | D4: Seeded Defect Catalog Code (fill) | E4: Linked Test Cases | F4: # Test Cases | G4: Detected in run? (fill: Detected / Not detected / Not run) | H4: Defect Log ID (fill)
A5: RI-01 | B5: Authentication | C5: Valid agents cannot log in after authentication changes | E5: TC-AUTH-V01 | F5: =COUNTIF('Test Cases'!$G$5:$G$109,"*"&A5&"*") -> 1
A6: RI-02 | B6: Authentication | C6: Locked or invalid agents get incorrect / misleading messages | E6: TC-AUTH-V02, TC-AUTH-V06, TC-AUTH-V07 | F6: =COUNTIF('Test Cases'!$G$5:$G$109,"*"&A6&"*") -> 3
A7: RI-03 | B7: Authentication | C7: Password policy not consistently enforced | E7: TC-AUTH-V08, TC-AUTH-V13 | F7: =COUNTIF('Test Cases'!$G$5:$G$109,"*"&A7&"*") -> 2
A8: RI-04 | B8: Client / KYC | C8: Client age eligibility rules (18-65) missed | E8: TC-CLI-V03, TC-CLI-V04 | F8: =COUNTIF('Test Cases'!$G$5:$G$109,"*"&A8&"*") -> 2
A9: RI-05 | B9: Client / KYC | C9: Future date of birth accepted | E9: TC-CLI-V05, TC-API-V03, TC-API-V12 | F9: =COUNTIF('Test Cases'!$G$5:$G$109,"*"&A9&"*") -> 3
A10: RI-06 | B10: Documents / Validation | C10: Mandatory KYC documents not enforced | E10: TC-DOC-V04, TC-API-V05 | F10: =COUNTIF('Test Cases'!$G$5:$G$109,"*"&A10&"*") -> 2
A11: RI-07 | B11: Client / KYC | C11: SSN not masked properly | E11: TC-CLI-V08 | F11: =COUNTIF('Test Cases'!$G$5:$G$109,"*"&A11&"*") -> 1
A12: RI-08 | B12: Client / KYC | C12: Income vs premium affordability not applied | E12: TC-CLI-V12 | F12: =COUNTIF('Test Cases'!$G$5:$G$109,"*"&A12&"*") -> 1
A13: RI-09 | B13: Product / Policy | C13: Product eligibility not validated against age / suitability | E13: TC-PROD-V07, TC-PROD-V08 | F13: =COUNTIF('Test Cases'!$G$5:$G$109,"*"&A13&"*") -> 2
A14: RI-10 | B14: Riders | C14: Rider coverage exceeds base face value | E14: TC-RIDER-V02 | F14: =COUNTIF('Test Cases'!$G$5:$G$109,"*"&A14&"*") -> 1
A15: RI-11 | B15: Riders | C15: Exclusive waiver riders both selectable | E15: TC-RIDER-V05 | F15: =COUNTIF('Test Cases'!$G$5:$G$109,"*"&A15&"*") -> 1
A16: RI-12 | B16: Product / Policy | C16: Premium not updated after configuration change | E16: TC-PROD-V05, TC-PROD-V06, TC-RIDER-V07 | F16: =COUNTIF('Test Cases'!$G$5:$G$109,"*"&A16&"*") -> 3
... A24: RI-20 | B24: Cross-cutting | C24: Failures hard to debug (no consistent evidence) | E24: TC-FW-01 | F24: =COUNTIF('Test Cases'!$G$5:$G$109,"*"&A24&"*") -> 1
A26: Detection rate | C26: =IF(COUNTIF(G5:G24,"Detected")+COUNTIF(G5:G24,"Not detected")=0,"n/a",COUNTIF(G5:G24,"Detected")/(COUNTIF(G5:G24,"Detected")+COUNTIF(G5:G24,"Not detected"))) -> n/a

Sheet Exploration Log
A1: Exploration Log - hands-on walkthrough of the LIVE application BEFORE trusting the scripts
A2: Time-boxed (see total). Yellow cells are for you. Walk the full journey once, then resolve each open item and record it where the last-but-one column says.
A4: Item | B4: What to find out | C4: Record the answer in | D4: Time-box (min) | E4: Dependent test cases | F4: # Dependent | G4: Status | H4: Value found (fill) | I4: Date (fill) | J4: Notes (fill)
A5: Q02 | B5: Base URL / port of the UI and API; reachable from the machine AND from the CI runner | C5: .env INSURANCE_BASE_URL, INSURANCE_API_URL | D5: 5 | F5: =IF(E5="",0,LEN(E5)-LEN(SUBSTITUTE(E5,"TC-","")))/3 -> 0 | G5: Not started
A6: Q03 | B6: API authentication (bearer token vs session cookie), header names, login response shape; payload field names for client / beneficiary / document calls | C6: .env API_AUTH_MODE, INSURANCE_API_KEY; api/helpers.js payloads | D6: 10 | F6: =IF(E6="",0,LEN(E6)-LEN(SUBSTITUTE(E6,"TC-","")))/3 -> 0 | G6: Not started
A7: Q04 | B7: Is read-only database access available? Engine, schema / data dictionary | C7: Unblocks DB-01..DB-10 (Blocked until then) | D7: 5 | E7: TC-DB-01, TC-DB-02, TC-DB-03, TC-DB-04, TC-DB-05, TC-DB-06, TC-DB-07, TC-DB-08, TC-DB-09, TC-DB-10 | F7: =IF(E7="",0,LEN(E7)-LEN(SUBSTITUTE(E7,"TC-","")))/3 -> 10 | G7: Not started
A8: Q06 | B8: Which seeded users exist: new agent, second agent, MFA agent; which can be locked / reset safely (disposable) | C8: .env AGENT_*_EMAIL | D8: 10 | E8: TC-AUTH-V09, TC-DASH-V02, TC-DASH-V03, TC-API-V08 | F8: =IF(E8="",0,LEN(E8)-LEN(SUBSTITUTE(E8,"TC-","")))/3 -> 4 | G8: Not started
A9: Q07 | B9: Lockout behaviour (5th failure locks? duration / unlock) and session timeout length | C9: .env LOCKOUT_ATTEMPTS, SESSION_TIMEOUT_SECONDS | D9: 5 | E9: TC-AUTH-V10 | F9: =IF(E9="",0,LEN(E9)-LEN(SUBSTITUTE(E9,"TC-","")))/3 -> 1 | G9: Not started
A10: Q08 | B10: How OTP is simulated (fixed code?) for login MFA and password reset | C10: .env OTP_CODE | D10: 5 | E10: TC-AUTH-V08, TC-AUTH-V09, TC-AUTH-V12 | F10: =IF(E10="",0,LEN(E10)-LEN(SUBSTITUTE(E10,"TC-","")))/3 -> 3 | G10: Not started
A11: Q09 | B11: Exact password policy rules and the change / reset page route | C11: config/messages.js passwordPolicy; tests/ui/auth.spec.js weak list | D11: 5 | E11: TC-AUTH-V08 | F11: =IF(E11="",0,LEN(E11)-LEN(SUBSTITUTE(E11,"TC-","")))/3 -> 1 | G11: Not started
A12: Q10 | B12: Age 18 and 65 inclusive? Age calculated on which date? | C12: .env AGE_BOUNDARY_INCLUSIVE | D12: 3 | F12: =IF(E12="",0,LEN(E12)-LEN(SUBSTITUTE(E12,"TC-","")))/3 -> 0 | G12: Not started
A13: Q11 | B13: Income vs premium affordability rule: block or warning, threshold, where it appears | C13: tests/ui/client.spec.js CLI-V12 data; config/messages.js affordability | D13: 5 | F13: =IF(E13="",0,LEN(E13)-LEN(SUBSTITUTE(E13,"TC-","")))/3 -> 0 | G13: Not started
A14: Q13 | B14: Face value min / max per product, product eligibility by age, suitability mismatch example, exact Whole Life product names | C14: .env FACE_VALUE_MIN/MAX, PRODUCT_NAME_PATTERN, INELIGIBLE_AGE*, SUITABILITY_PRODUCT_PATTERN | D14: 10 | E14: TC-PROD-V03, TC-PROD-V04, TC-PROD-V07, TC-PROD-V08 | F14: =IF(E14="",0,LEN(E14)-LEN(SUBSTITUTE(E14,"TC-","")))/3 -> 4 | G14: Not started
A15: Q14 | B15: Valid payment-term / policy-term combinations | C15: tests/ui/product.spec.js PROD-V09 | D15: 3 | F15: =IF(E15="",0,LEN(E15)-LEN(SUBSTITUTE(E15,"TC-","")))/3 -> 0 | G15: Not started
A16: Q15 | B16: Maximum rider count, age-restricted rider, which waiver riders are exclusive, rider names | C16: .env MAX_RIDERS, RIDER_*_PATTERN | D16: 5 | E16: TC-RIDER-V03, TC-RIDER-V04, TC-RIDER-V05 | F16: =IF(E16="",0,LEN(E16)-LEN(SUBSTITUTE(E16,"TC-","")))/3 -> 3 | G16: Not started
A17: Q17 | B17: Maximum upload size and which documents are mandatory | C17: .env MAX_UPLOAD_MB | D17: 3 | E17: TC-DOC-V03 | F17: =IF(E17="",0,LEN(E17)-LEN(SUBSTITUTE(E17,"TC-","")))/3 -> 1 | G17: Not started
A18: Q21 | B18: Can tests create their own draft applications (UI and API)? Is cleanup possible? | C18: api/helpers.js disposableDraft() | D18: 5 | E18: TC-API-V03, TC-API-V04, TC-API-V05 | F18: =IF(E18="",0,LEN(E18)-LEN(SUBSTITUTE(E18,"TC-","")))/3 -> 3 | G18: Not started
A19: ROUTES | B19: Walk the full journey once; note the URL of every step, the application id pattern in the URL, and the exact wording of validation messages | C19: config/routes.js, config/messages.js, config/selectors.js (run npm run discover) | D19: 20 | F19: =IF(E19="",0,LEN(E19)-LEN(SUBSTITUTE(E19,"TC-","")))/3 -> 0 | G19: Not started
A21: Total time-box (min) | D21: =SUM(D5:D19) -> 99
A22: Items done | D22: =COUNTIF(G5:G19,"Done")&" of "&COUNTA(A5:A19) -> 0 of 15
A24: Exit rule: do not start broad automation until ROUTES, Q02, Q03 and Q06 are Done. Other items may stay open - their tests skip with a reason instead of failing falsely.

Sheet Limitations
A1: Known limitations and blocked areas
A3: # | B3: Area | C3: Limitation / blocked item | D3: Impact | E3: Resolution
A4: 1 | B4: Execution | C4: The automation has not been run against the real lab application (no access when it was built). | D4: Selectors, routes and messages are unconfirmed | E4: Complete the Exploration Log, run npm run discover and npm run verify:selectors, then run the smoke suite
A5: 2 | B5: Selectors | C5: Only login-email, login-password, login-submit are confirmed. Other test ids are conventions; every control has a role/label fallback. | D5: Some locators may need correcting | E5: config/selectors.js is the only file to edit
A6: 3 | B6: Database | C6: No DB engine, schema or access (Q04). DB-01..DB-10 are Blocked. | D6: 10 cases not automated | E6: API reads are used as a proxy where the linked scenario has an API test
A7: 4 | B7: Business rules | C7: Face value limits, max riders, upload size, lockout, age boundary, affordability rule are TBC. | D7: Dependent tests skip with a reason instead of failing | E7: Resolve in exploration and set the .env values
A8: 5 | B8: Users | C8: Only agent.valid and agent.locked are confirmed. New / second / MFA / lockout / reset users need names (Q06). | D8: Isolation, empty-state, MFA, lockout, reset tests skip | E8: Set AGENT_*_EMAIL in .env
A9: 6 | B9: Destructive tests | C9: AUTH-V07 locks an account; AUTH-V08/V13 may change a password if the app is defective. | D9: Disposable users required | E9: Use AGENT_LOCKOUT_* and AGENT_RESET_* only with throw-away users
A10: 7 | B10: API payloads | C10: API field names are unconfirmed (Q03). Tests send a valid control request first and skip if it is rejected. | D10: No false defects, but some API tests may skip | E10: Adjust api/helpers.js after exploration
A11: 8 | B11: Shared lab | C11: One worker by default. Parallel runs add load and can collide on shared data. | D11: Slower runs | E11: Raise WORKERS only after a stable single-worker baseline
A12: 9 | B12: Evidence | C12: Traces and videos cannot be masked, so they are disabled for KYC / SSN tests. Masked screenshots are attached instead. | D12: Less debug detail for 4 sensitive tests | E12: Use the masked screenshot and diagnostics.json
A13: 10 | B13: Cross-browser | C13: Chromium primary. Firefox / WebKit smoke only when CROSS_BROWSER=true. | D13: Limited cross-browser coverage | E13: Enable per the plan before release
A14: 11 | B14: Priorities | C14: P1 re-cut from 52 to 19 cases by author judgement. | D14: Mentor / product owner should confirm the gate | E14: Review the Release Gate sheet
A15: 12 | B15: Risk links | C15: 36 cases were not named in the Submission 1 "Covered by" column and were linked to the closest risk by judgement. | D15: Traceability partly judgemental | E15: Review in the Traceability - Risks sheet
